[23/03/2017 13:20] ERROR red load_cogs 562: You need the imgurpython module to use this.
pip3 install imgurpython
Traceback (most recent call last):
  File "red.py", line 559, in load_cogs
    owner_cog._load_cog(extension)
  File "/home/alex/Discord-Bot/Red-DiscordBot/cogs/owner.py", line 799, in _load_cog
    self.bot.load_extension(mod_obj.__name__)
  File "/usr/local/lib/python3.5/dist-packages/discord/ext/commands/bot.py", line 738, in load_extension
    lib.setup(self)
  File "/home/alex/Discord-Bot/Red-DiscordBot/cogs/image.py", line 150, in setup
    raise RuntimeError("You need the imgurpython module to use this.\n"
RuntimeError: You need the imgurpython module to use this.
pip3 install imgurpython
[23/03/2017 13:20] ERROR red load_cogs 562: You need to run `pip3 install youtube_dl`
Traceback (most recent call last):
  File "red.py", line 559, in load_cogs
    owner_cog._load_cog(extension)
  File "/home/alex/Discord-Bot/Red-DiscordBot/cogs/owner.py", line 799, in _load_cog
    self.bot.load_extension(mod_obj.__name__)
  File "/usr/local/lib/python3.5/dist-packages/discord/ext/commands/bot.py", line 738, in load_extension
    lib.setup(self)
  File "/home/alex/Discord-Bot/Red-DiscordBot/cogs/audio.py", line 2219, in setup
    raise RuntimeError("You need to run `pip3 install youtube_dl`")
RuntimeError: You need to run `pip3 install youtube_dl`
[03/10/2017 12:11] ERROR red <module> 622: Fatal exception, attempting graceful logout
Traceback (most recent call last):
  File "/usr/local/lib/python3.5/dist-packages/aiohttp/connector.py", line 601, in _create_direct_connection
    local_addr=self._local_addr)
  File "/usr/lib/python3.5/asyncio/base_events.py", line 713, in create_connection
    sock, protocol_factory, ssl, server_hostname)
  File "/usr/lib/python3.5/asyncio/base_events.py", line 736, in _create_connection_transport
    yield from waiter
  File "/usr/lib/python3.5/asyncio/futures.py", line 361, in __iter__
    yield self  # This tells Task to wait for completion.
  File "/usr/lib/python3.5/asyncio/tasks.py", line 296, in _wakeup
    future.result()
  File "/usr/lib/python3.5/asyncio/futures.py", line 274, in result
    raise self._exception
  File "/usr/lib/python3.5/asyncio/sslproto.py", line 493, in data_received
    ssldata, appdata = self._sslpipe.feed_ssldata(data)
  File "/usr/lib/python3.5/asyncio/sslproto.py", line 201, in feed_ssldata
    self._sslobj.do_handshake()
  File "/usr/lib/python3.5/ssl.py", line 633, in do_handshake
    self._sslobj.do_handshake()
ssl.SSLError: [SSL: CERTIFICATE_VERIFY_FAILED] certificate verify failed (_ssl.c:645)

The above exception was the direct cause of the following exception:

Traceback (most recent call last):
  File "/usr/local/lib/python3.5/dist-packages/aiohttp/connector.py", line 304, in connect
    yield from self._create_connection(req)
  File "/usr/local/lib/python3.5/dist-packages/aiohttp/connector.py", line 578, in _create_connection
    transport, proto = yield from self._create_direct_connection(req)
  File "/usr/local/lib/python3.5/dist-packages/aiohttp/connector.py", line 624, in _create_direct_connection
    (req.host, req.port, exc.strerror)) from exc
aiohttp.errors.ClientOSError: [Errno 1] Can not connect to discordapp.com:443 [[SSL: CERTIFICATE_VERIFY_FAILED] certificate verify failed (_ssl.c:645)]

The above exception was the direct cause of the following exception:

Traceback (most recent call last):
  File "red.py", line 603, in <module>
    loop.run_until_complete(main(bot))
  File "/usr/lib/python3.5/asyncio/base_events.py", line 387, in run_until_complete
    return future.result()
  File "/usr/lib/python3.5/asyncio/futures.py", line 274, in result
    raise self._exception
  File "/usr/lib/python3.5/asyncio/tasks.py", line 241, in _step
    result = coro.throw(exc)
  File "red.py", line 592, in main
    yield from bot.connect()
  File "/usr/local/lib/python3.5/dist-packages/discord/client.py", line 452, in connect
    self.ws = yield from DiscordWebSocket.from_client(self, resume=resume)
  File "/usr/local/lib/python3.5/dist-packages/discord/gateway.py", line 193, in from_client
    gateway = yield from client.http.get_gateway()
  File "/usr/local/lib/python3.5/dist-packages/discord/http.py", line 631, in get_gateway
    data = yield from self.request(Route('GET', '/gateway'))
  File "/usr/local/lib/python3.5/dist-packages/discord/http.py", line 136, in request
    r = yield from self.session.request(method, url, **kwargs)
  File "/usr/local/lib/python3.5/dist-packages/aiohttp/client.py", line 555, in __iter__
    resp = yield from self._coro
  File "/usr/local/lib/python3.5/dist-packages/aiohttp/client.py", line 198, in _request
    conn = yield from self._connector.connect(req)
  File "/usr/local/lib/python3.5/dist-packages/aiohttp/connector.py", line 314, in connect
    .format(key, exc.strerror)) from exc
aiohttp.errors.ClientOSError: [Errno 1] Cannot connect to host discordapp.com:443 ssl:True [Can not connect to discordapp.com:443 [[SSL: CERTIFICATE_VERIFY_FAILED] certificate verify failed (_ssl.c:645)]]
